<?xml version="1.0"?>
<robot name="com760group30Bot">

  <link name="base_footprint"/>

  <joint name="base_joint" type="fixed">
    <parent link="base_footprint"/>
    <child link="base_link"/>
    <origin xyz="0 0 0.05" rpy="0 0 0"/>
  </joint>

  <link name="base_link">
    <visual>
      <geometry>
        <box size="0.28 0.20 0.08"/>
      </geometry>
      <material name="dark_grey">
        <color rgba="0.3 0.3 0.3 1.0"/>
      </material>
    </visual>
    <collision>
      <geometry>
        <box size="0.28 0.20 0.08"/>
      </geometry>
    </collision>
    <inertial>
      <mass value="2.0"/>
      <inertia ixx="0.0166" ixy="0" ixz="0"
               iyy="0.0194" iyz="0"
               izz="0.0316"/>
    </inertial>
  </link>

  <joint name="left_wheel_joint" type="continuous">
    <parent link="base_link"/>
    <child link="left_wheel"/>
    <origin xyz="0.0 0.12 -0.025" rpy="-1.5707 0 0"/>
    <axis xyz="0 0 1"/>
  </joint>

  <link name="left_wheel">
    <visual>
      <geometry>
        <cylinder radius="0.045" length="0.03"/>
      </geometry>
      <material name="black">
        <color rgba="0.1 0.1 0.1 1.0"/>
      </material>
    </visual>
    <collision>
      <geometry>
        <cylinder radius="0.045" length="0.03"/>
      </geometry>
    </collision>
    <inertial>
      <mass value="0.3"/>
      <inertia ixx="0.000152" ixy="0" ixz="0"
               iyy="0.000152" iyz="0"
               izz="0.000304"/>
    </inertial>
  </link>

  <joint name="right_wheel_joint" type="continuous">
    <parent link="base_link"/>
    <child link="right_wheel"/>
    <origin xyz="0.0 -0.12 -0.025" rpy="-1.5707 0 0"/>
    <axis xyz="0 0 1"/>
  </joint>

  <link name="right_wheel">
    <visual>
      <geometry>
        <cylinder radius="0.045" length="0.03"/>
      </geometry>
      <material name="black"/>
    </visual>
    <collision>
      <geometry>
        <cylinder radius="0.045" length="0.03"/>
      </geometry>
    </collision>
    <inertial>
      <mass value="0.3"/>
      <inertia ixx="0.000152" ixy="0" ixz="0"
               iyy="0.000152" iyz="0"
               izz="0.000304"/>
    </inertial>
  </link>

  <joint name="caster_joint" type="fixed">
    <parent link="base_link"/>
    <child link="caster_wheel"/>
    <origin xyz="0.12 0 -0.04" rpy="0 0 0"/>
  </joint>

  <link name="caster_wheel">
    <visual>
      <geometry>
        <sphere radius="0.02"/>
      </geometry>
      <material name="dark_grey"/>
    </visual>
    <collision>
      <geometry>
        <sphere radius="0.02"/>
      </geometry>
    </collision>
    <inertial>
      <mass value="0.05"/>
      <inertia ixx="0.000004" ixy="0" ixz="0"
               iyy="0.000004" iyz="0"
               izz="0.000004"/>
    </inertial>
  </link>

  <joint name="laser_joint" type="fixed">
    <parent link="base_link"/>
    <child link="laser_link"/>
    <origin xyz="0.12 0 0.06" rpy="0 0 0"/>
  </joint>

  <link name="laser_link">
    <visual>
      <geometry>
        <box size="0.04 0.04 0.03"/>
      </geometry>
      <material name="yellow">
        <color rgba="0.9 0.8 0.0 1.0"/>
      </material>
    </visual>
    <inertial>
      <mass value="0.05"/>
      <inertia ixx="0.000001" ixy="0" ixz="0"
               iyy="0.000001" iyz="0"
               izz="0.000001"/>
    </inertial>
  </link>

  <gazebo>
    <plugin name="differential_drive_controller"
            filename="libgazebo_ros_diff_drive.so">
      <robotNamespace>/com760group30Bot</robotNamespace>
      <leftJoint>left_wheel_joint</leftJoint>
      <rightJoint>right_wheel_joint</rightJoint>
      <wheelSeparation>0.24</wheelSeparation>
      <wheelDiameter>0.09</wheelDiameter>
      <wheelTorque>10</wheelTorque>
      <wheelAcceleration>1.5</wheelAcceleration>
      <commandTopic>/com760group30Bot/cmd_vel</commandTopic>
      <odometryTopic>/com760group30Bot/odom</odometryTopic>
      <odometryFrame>odom</odometryFrame>
      <robotBaseFrame>base_footprint</robotBaseFrame>
      <publishWheelTF>true</publishWheelTF>
      <publishOdom>true</publishOdom>
      <updateRate>30</updateRate>
    </plugin>
  </gazebo>

  <gazebo reference="laser_link">
    <sensor type="ray" name="mine_laser">
      <pose>0 0 0 0 0 0</pose>
      <visualize>true</visualize>
      <update_rate>20</update_rate>
      <ray>
        <scan>
          <horizontal>
            <samples>360</samples>
            <resolution>1</resolution>
            <min_angle>-3.14159</min_angle>
            <max_angle>3.14159</max_angle>
          </horizontal>
        </scan>
        <range>
          <min>0.10</min>
          <max>10.0</max>
          <resolution>0.01</resolution>
        </range>
        <noise>
          <type>gaussian</type>
          <mean>0.0</mean>
          <stddev>0.01</stddev>
        </noise>
      </ray>
      <plugin name="laser_controller"
              filename="libgazebo_ros_laser.so">
        <robotNamespace>/com760group30Bot</robotNamespace>
        <topicName>/com760group30Bot/laser/scan</topicName>
        <frameName>laser_link</frameName>
      </plugin>
    </sensor>
    <material>Gazebo/Yellow</material>
  </gazebo>

  <gazebo reference="base_link">
    <material>Gazebo/DarkGrey</material>
  </gazebo>

  <gazebo reference="left_wheel">
    <material>Gazebo/Black</material>
    <mu1>1.0</mu1>
    <mu2>1.0</mu2>
  </gazebo>

  <gazebo reference="right_wheel">
    <material>Gazebo/Black</material>
    <mu1>1.0</mu1>
    <mu2>1.0</mu2>
  </gazebo>

  <gazebo reference="caster_wheel">
    <material>Gazebo/DarkGrey</material>
    <mu1>0.0</mu1>
    <mu2>0.0</mu2>
  </gazebo>

</robot>